ERROR REPORT: analysis_20250913_182718
==================================================

Phase: analysis
Timestamp: 2025-09-13T18:27:18.072660+00:00
Document: negative_test_1.txt
Error: Verification LLM call failed: litellm.AuthenticationError: AuthenticationError: OpenrouterException - {"error":{"message":"No auth credentials found","code":401}}

Context:
{
  "framework_path": "/Volumes/code/discernus/projects/micro_test_experiment/sentiment_binary_v1.md",
  "model": "vertex_ai/gemini-2.5-pro"
}

Traceback:
Traceback (most recent call last):
  File "/Volumes/code/discernus/discernus/core/show_your_work_orchestrator.py", line 239, in _execute_analysis_phase
    verification_result = self.verification_agent.verify_analysis(
        analysis_artifact_id=analysis_result["scores_artifact"],
        work_artifact_id=analysis_result["work_artifact"],
        model=None  # Auto-select verifier model
    )
  File "/Volumes/code/discernus/discernus/agents/verification_agent/agent.py", line 111, in verify_analysis
    raise Exception(f"Verification LLM call failed: {metadata.get('error', 'Unknown error')}")
Exception: Verification LLM call failed: litellm.AuthenticationError: AuthenticationError: OpenrouterException - {"error":{"message":"No auth credentials found","code":401}}
