{
  "error_id": "analysis_20250913_182718",
  "phase": "analysis",
  "timestamp": "2025-09-13T18:27:18.072660+00:00",
  "error_message": "Verification LLM call failed: litellm.AuthenticationError: AuthenticationError: OpenrouterException - {\"error\":{\"message\":\"No auth credentials found\",\"code\":401}}",
  "document_name": "negative_test_1.txt",
  "context": {
    "framework_path": "/Volumes/code/discernus/projects/micro_test_experiment/sentiment_binary_v1.md",
    "model": "vertex_ai/gemini-2.5-pro"
  },
  "traceback": "Traceback (most recent call last):\n  File \"/Volumes/code/discernus/discernus/core/show_your_work_orchestrator.py\", line 239, in _execute_analysis_phase\n    verification_result = self.verification_agent.verify_analysis(\n        analysis_artifact_id=analysis_result[\"scores_artifact\"],\n        work_artifact_id=analysis_result[\"work_artifact\"],\n        model=None  # Auto-select verifier model\n    )\n  File \"/Volumes/code/discernus/discernus/agents/verification_agent/agent.py\", line 111, in verify_analysis\n    raise Exception(f\"Verification LLM call failed: {metadata.get('error', 'Unknown error')}\")\nException: Verification LLM call failed: litellm.AuthenticationError: AuthenticationError: OpenrouterException - {\"error\":{\"message\":\"No auth credentials found\",\"code\":401}}\n",
  "run_folder": "/Volumes/code/discernus/projects/micro_test_experiment/show_your_work_run"
}