ERROR REPORT: orchestrator_error_20250913_182718
==================================================

Phase: orchestrator_error
Timestamp: 2025-09-13T18:27:18.073515+00:00
Error: Analysis phase failed: /Volumes/code/discernus/projects/micro_test_experiment/show_your_work_run/errors/analysis_20250913_182718.json

Context:
{
  "error": "Analysis phase failed: /Volumes/code/discernus/projects/micro_test_experiment/show_your_work_run/errors/analysis_20250913_182718.json",
  "error_type": "Exception"
}

Traceback:
Traceback (most recent call last):
  File "/Volumes/code/discernus/discernus/core/show_your_work_orchestrator.py", line 239, in _execute_analysis_phase
    verification_result = self.verification_agent.verify_analysis(
        analysis_artifact_id=analysis_result["scores_artifact"],
        work_artifact_id=analysis_result["work_artifact"],
        model=None  # Auto-select verifier model
    )
  File "/Volumes/code/discernus/discernus/agents/verification_agent/agent.py", line 111, in verify_analysis
    raise Exception(f"Verification LLM call failed: {metadata.get('error', 'Unknown error')}")
Exception: Verification LLM call failed: litellm.AuthenticationError: AuthenticationError: OpenrouterException - {"error":{"message":"No auth credentials found","code":401}}

During handling of the above exception, another exception occurred:

Traceback (most recent call last):
  File "/Volumes/code/discernus/discernus/core/show_your_work_orchestrator.py", line 135, in execute_experiment
    analysis_results = self._execute_analysis_phase(
        framework_path, corpus_path, analysis_model
    )
  File "/Volumes/code/discernus/discernus/core/show_your_work_orchestrator.py", line 257, in _execute_analysis_phase
    raise Exception(f"Analysis phase failed: {error_details}")
Exception: Analysis phase failed: /Volumes/code/discernus/projects/micro_test_experiment/show_your_work_run/errors/analysis_20250913_182718.json
