ERROR REPORT: orchestrator_error_20250913_183255
==================================================

Phase: orchestrator_error
Timestamp: 2025-09-13T18:32:55.965019+00:00
Error: Statistical phase failed: /Volumes/code/discernus/projects/micro_test_experiment/show_your_work_run_logged/errors/statistical_20250913_183255.json

Context:
{
  "error": "Statistical phase failed: /Volumes/code/discernus/projects/micro_test_experiment/show_your_work_run_logged/errors/statistical_20250913_183255.json",
  "error_type": "Exception"
}

Traceback:
Traceback (most recent call last):
  File "/Volumes/code/discernus/discernus/core/show_your_work_orchestrator.py", line 314, in _execute_statistical_phase
    statistical_result = self.statistical_agent.execute_statistical_analysis(
                         ^^^^^^^^^^^^^^^^^^^^^^^^^^^^^^^^^^^^^^^^^^^^^^^^^^^
AttributeError: 'StatisticalPlanningExecutionAgent' object has no attribute 'execute_statistical_analysis'

During handling of the above exception, another exception occurred:

Traceback (most recent call last):
  File "/Volumes/code/discernus/discernus/core/show_your_work_orchestrator.py", line 161, in execute_experiment
    statistical_results = self._execute_statistical_phase(
        analysis_results["artifacts"], statistical_model
    )
  File "/Volumes/code/discernus/discernus/core/show_your_work_orchestrator.py", line 353, in _execute_statistical_phase
    raise Exception(f"Statistical phase failed: {error_details}")
Exception: Statistical phase failed: /Volumes/code/discernus/projects/micro_test_experiment/show_your_work_run_logged/errors/statistical_20250913_183255.json
